Traceback (most recent call last):
  File "/home/bdcdo/Desktop/dev/curso-polars/venv2/lib/python3.12/site-packages/jupyter_cache/executors/utils.py", line 58, in single_nb_execution
    executenb(
  File "/home/bdcdo/Desktop/dev/curso-polars/venv2/lib/python3.12/site-packages/nbclient/client.py", line 1319, in execute
    return NotebookClient(nb=nb, resources=resources, km=km, **kwargs).execute()
           ^^^^^^^^^^^^^^^^^^^^^^^^^^^^^^^^^^^^^^^^^^^^^^^^^^^^^^^^^^^^^^^^^^^^^
  File "/home/bdcdo/Desktop/dev/curso-polars/venv2/lib/python3.12/site-packages/jupyter_core/utils/__init__.py", line 165, in wrapped
    return loop.run_until_complete(inner)
           ^^^^^^^^^^^^^^^^^^^^^^^^^^^^^^
  File "/usr/lib/python3.12/asyncio/base_events.py", line 687, in run_until_complete
    return future.result()
           ^^^^^^^^^^^^^^^
  File "/home/bdcdo/Desktop/dev/curso-polars/venv2/lib/python3.12/site-packages/nbclient/client.py", line 709, in async_execute
    await self.async_execute_cell(
  File "/home/bdcdo/Desktop/dev/curso-polars/venv2/lib/python3.12/site-packages/nbclient/client.py", line 1062, in async_execute_cell
    await self._check_raise_for_error(cell, cell_index, exec_reply)
  File "/home/bdcdo/Desktop/dev/curso-polars/venv2/lib/python3.12/site-packages/nbclient/client.py", line 918, in _check_raise_for_error
    raise CellExecutionError.from_cell_and_msg(cell, exec_reply_content)
nbclient.exceptions.CellExecutionError: An error occurred while executing the following cell:
------------------
# Mas, como nÃ£o teve um import especÃ­fico, sem o "math." antes nÃ£o funciona
factorial(8)
------------------


[31m---------------------------------------------------------------------------[39m
[31mNameError[39m                                 Traceback (most recent call last)
[36mCell[39m[36m [39m[32mIn[9][39m[32m, line 2[39m
[32m      1[39m [38;5;66;03m# Mas, como nÃ£o teve um import especÃ­fico, sem o "math." antes nÃ£o funciona[39;00m
[32m----> [39m[32m2[39m [43mfactorial[49m([32m8[39m)

[31mNameError[39m: name 'factorial' is not defined

